using System;
using System.Collections.Generic;
using System.Threading;
using System.Threading.Tasks;

namespace Nito.Async
{
    /// <summary>
    /// A task completion source that forces task continuations to execute asynchronously. All members are fully threadsafe.
    /// </summary>
    internal sealed class AsyncTaskSource<T>
    {
        /// <summary>
        /// The underlying task completion source.
        /// </summary>
        private readonly TaskCompletionSource<T> _tcs;

        /// <summary>
        /// Creates a new asynchronous task source.
        /// </summary>
        public AsyncTaskSource()
        {
            _tcs = new TaskCompletionSource<T>(TaskCreationOptions.DenyChildAttach | TaskCreationOptions.RunContinuationsAsynchronously);
        }

        /// <summary>
        /// Gets the task that is controlled by this source.
        /// </summary>
        public Task<T> Task {  get { return _tcs.Task; } }

        /// <summary>
        /// Attempts to complete the task with the specified result value. Returns <c>false</c> if the task is already completed.
        /// </summary>
        /// <param name="result">The result value for the task.</param>
        public bool TrySetResult(T result)
        {
            return _tcs.TrySetResult(result);
        }

        /// <summary>
        /// Attempts to complete the task as faulted with the specified exception. Returns <c>false</c> if the task is already completed.
        /// </summary>
        /// <param name="exception">The exception for the task.</param>
        public bool TrySetException(Exception exception)
        {
            return _tcs.TrySetException(exception);
        }

        /// <summary>
        /// Attempts to complete the task as faulted with the specified exceptions. Returns <c>false</c> if the task is already completed.
        /// </summary>
        /// <param name="exception">The exceptions for the task.</param>
        public bool TrySetException(IEnumerable<Exception> exceptions)
        {
            return _tcs.TrySetException(exceptions);
        }

        /// <summary>
        /// Attempts to complete the task as canceled. Returns <c>false</c> if the task is already completed.
        /// </summary>
        public bool TrySetCanceled()
        {
            return _tcs.TrySetCanceled();
        }

        /// <summary>
        /// Attempts to complete the task as canceled with the specified cancellation token. Returns <c>false</c> if the task is already completed.
        /// </summary>
        /// <param name="cancellationToken">The cancellation token for the task.</param>
        public bool TrySetCanceled(CancellationToken cancellationToken)
        {
            return _tcs.TrySetCanceled(cancellationToken);
        }
    }
}